ERROR on Wrong Passowrd:


Traceback (most recent call last):
  File "server.py", line 8, in <module>
    print mysql.query_db("SELECT * FROM users")
  File
"/home/pravindr/coding-dojo/py/week4/a_mysql_conn_err/mysqlconnection.py",
line 24, in query_db
    result = self.db.session.execute(text(query), data)
  File
"/home/pravindr/coding-dojo/py/week4/venv/lib/python2.7/site-packages/sqlalchemy/orm/scoping.py",
line 153, in do
    return getattr(self.registry(), name)(*args, **kwargs)
  File
"/home/pravindr/coding-dojo/py/week4/venv/lib/python2.7/site-packages/sqlalchemy/orm/session.py",
line 1176, in execute
    bind, close_with_result=True).execute(clause, params or {})
  File
"/home/pravindr/coding-dojo/py/week4/venv/lib/python2.7/site-packages/sqlalchemy/orm/session.py",
line 1040, in _connection_for_bind
    engine, execution_options)
  File
"/home/pravindr/coding-dojo/py/week4/venv/lib/python2.7/site-packages/sqlalchemy/orm/session.py",
line 409, in _connection_for_bind
    conn = bind.contextual_connect()
  File
"/home/pravindr/coding-dojo/py/week4/venv/lib/python2.7/site-packages/sqlalchemy/engine/base.py",
line 2123, in contextual_connect
    self._wrap_pool_connect(self.pool.connect, None),
  File
"/home/pravindr/coding-dojo/py/week4/venv/lib/python2.7/site-packages/sqlalchemy/engine/base.py",
line 2162, in _wrap_pool_connect
    e, dialect, self)
  File
"/home/pravindr/coding-dojo/py/week4/venv/lib/python2.7/site-packages/sqlalchemy/engine/base.py",
line 1476, in _handle_dbapi_exception_noconnection
    exc_info
  File
"/home/pravindr/coding-dojo/py/week4/venv/lib/python2.7/site-packages/sqlalchemy/util/compat.py",
line 203, in raise_from_cause
    reraise(type(exception), exception, tb=exc_tb, cause=cause)
  File
"/home/pravindr/coding-dojo/py/week4/venv/lib/python2.7/site-packages/sqlalchemy/engine/base.py",
line 2158, in _wrap_pool_connect
    return fn()
  File
"/home/pravindr/coding-dojo/py/week4/venv/lib/python2.7/site-packages/sqlalchemy/pool.py",
line 403, in connect
    return _ConnectionFairy._checkout(self)
  File
"/home/pravindr/coding-dojo/py/week4/venv/lib/python2.7/site-packages/sqlalchemy/pool.py",
line 782, in _checkout
    fairy = _ConnectionRecord.checkout(pool)
  File
"/home/pravindr/coding-dojo/py/week4/venv/lib/python2.7/site-packages/sqlalchemy/pool.py",
line 532, in checkout
    rec = pool._do_get()
  File
"/home/pravindr/coding-dojo/py/week4/venv/lib/python2.7/site-packages/sqlalchemy/pool.py",
line 1186, in _do_get
    self._dec_overflow()
  File
"/home/pravindr/coding-dojo/py/week4/venv/lib/python2.7/site-packages/sqlalchemy/util/langhelpers.py",
line 66, in __exit__
    compat.reraise(exc_type, exc_value, exc_tb)
  File
"/home/pravindr/coding-dojo/py/week4/venv/lib/python2.7/site-packages/sqlalchemy/pool.py",
line 1183, in _do_get
    return self._create_connection()
  File
"/home/pravindr/coding-dojo/py/week4/venv/lib/python2.7/site-packages/sqlalchemy/pool.py",
line 350, in _create_connection
    return _ConnectionRecord(self)
  File
"/home/pravindr/coding-dojo/py/week4/venv/lib/python2.7/site-packages/sqlalchemy/pool.py",
line 477, in __init__
    self.__connect(first_connect_check=True)
  File
"/home/pravindr/coding-dojo/py/week4/venv/lib/python2.7/site-packages/sqlalchemy/pool.py",
line 667, in __connect
    connection = pool._invoke_creator(self)
  File
"/home/pravindr/coding-dojo/py/week4/venv/lib/python2.7/site-packages/sqlalchemy/engine/strategies.py",
line 105, in connect
    return dialect.connect(*cargs, **cparams)
  File
"/home/pravindr/coding-dojo/py/week4/venv/lib/python2.7/site-packages/sqlalchemy/engine/default.py",
line 410, in connect
    return self.dbapi.connect(*cargs, **cparams)
  File
"/home/pravindr/coding-dojo/py/week4/venv/lib/python2.7/site-packages/MySQLdb/__init__.py",
line 81, in Connect
    return Connection(*args, **kwargs)
  File
"/home/pravindr/coding-dojo/py/week4/venv/lib/python2.7/site-packages/MySQLdb/connections.py",
line 206, in __init__
    super(Connection, self).__init__(*args, **kwargs2)
sqlalchemy.exc.OperationalError: (_mysql_exceptions.OperationalError) (1045,
"Access denied for user 'root'@'localhost' (using password:
YES)") (Background on this error at: http://sqlalche.me/e/e3q8)





ERROR on wrong PORT

Traceback (most recent call last):
  File "server.py", line 8, in <module>
    print mysql.query_db("SELECT * FROM users")
  File
"/home/pravindr/coding-dojo/py/week4/a_mysql_conn_err/mysqlconnection.py",
line 24, in query_db
    result = self.db.session.execute(text(query), data)
  File
"/home/pravindr/coding-dojo/py/week4/venv/lib/python2.7/site-packages/sqlalchemy/orm/scoping.py",
line 153, in do
    return getattr(self.registry(), name)(*args, **kwargs)
  File
"/home/pravindr/coding-dojo/py/week4/venv/lib/python2.7/site-packages/sqlalchemy/orm/session.py",
line 1176, in execute
    bind, close_with_result=True).execute(clause, params or {})
  File
"/home/pravindr/coding-dojo/py/week4/venv/lib/python2.7/site-packages/sqlalchemy/orm/session.py",
line 1040, in _connection_for_bind
    engine, execution_options)
  File
"/home/pravindr/coding-dojo/py/week4/venv/lib/python2.7/site-packages/sqlalchemy/orm/session.py",
line 409, in _connection_for_bind
    conn = bind.contextual_connect()
  File
"/home/pravindr/coding-dojo/py/week4/venv/lib/python2.7/site-packages/sqlalchemy/engine/base.py",
line 2123, in contextual_connect
    self._wrap_pool_connect(self.pool.connect, None),
  File
"/home/pravindr/coding-dojo/py/week4/venv/lib/python2.7/site-packages/sqlalchemy/engine/base.py",
line 2162, in _wrap_pool_connect
    e, dialect, self)
  File
"/home/pravindr/coding-dojo/py/week4/venv/lib/python2.7/site-packages/sqlalchemy/engine/base.py",
line 1476, in _handle_dbapi_exception_noconnection
    exc_info
  File
"/home/pravindr/coding-dojo/py/week4/venv/lib/python2.7/site-packages/sqlalchemy/util/compat.py",
line 203, in raise_from_cause
    reraise(type(exception), exception, tb=exc_tb, cause=cause)
  File
"/home/pravindr/coding-dojo/py/week4/venv/lib/python2.7/site-packages/sqlalchemy/engine/base.py",
line 2158, in _wrap_pool_connect
    return fn()
  File
"/home/pravindr/coding-dojo/py/week4/venv/lib/python2.7/site-packages/sqlalchemy/pool.py",
line 403, in connect
    return _ConnectionFairy._checkout(self)
  File
"/home/pravindr/coding-dojo/py/week4/venv/lib/python2.7/site-packages/sqlalchemy/pool.py",
line 782, in _checkout
    fairy = _ConnectionRecord.checkout(pool)
  File
"/home/pravindr/coding-dojo/py/week4/venv/lib/python2.7/site-packages/sqlalchemy/pool.py",
line 532, in checkout
    rec = pool._do_get()
  File
"/home/pravindr/coding-dojo/py/week4/venv/lib/python2.7/site-packages/sqlalchemy/pool.py",
line 1186, in _do_get
    self._dec_overflow()
  File
"/home/pravindr/coding-dojo/py/week4/venv/lib/python2.7/site-packages/sqlalchemy/util/langhelpers.py",
line 66, in __exit__
    compat.reraise(exc_type, exc_value, exc_tb)
  File
"/home/pravindr/coding-dojo/py/week4/venv/lib/python2.7/site-packages/sqlalchemy/pool.py",
line 1183, in _do_get
    return self._create_connection()
  File
"/home/pravindr/coding-dojo/py/week4/venv/lib/python2.7/site-packages/sqlalchemy/pool.py",
line 350, in _create_connection
    return _ConnectionRecord(self)
  File
"/home/pravindr/coding-dojo/py/week4/venv/lib/python2.7/site-packages/sqlalchemy/pool.py",
line 477, in __init__
    self.__connect(first_connect_check=True)
  File
"/home/pravindr/coding-dojo/py/week4/venv/lib/python2.7/site-packages/sqlalchemy/pool.py",
line 667, in __connect
    connection = pool._invoke_creator(self)
  File
"/home/pravindr/coding-dojo/py/week4/venv/lib/python2.7/site-packages/sqlalchemy/engine/strategies.py",
line 105, in connect
    return dialect.connect(*cargs, **cparams)
  File
"/home/pravindr/coding-dojo/py/week4/venv/lib/python2.7/site-packages/sqlalchemy/engine/default.py",
line 410, in connect
    return self.dbapi.connect(*cargs, **cparams)
  File
"/home/pravindr/coding-dojo/py/week4/venv/lib/python2.7/site-packages/MySQLdb/__init__.py",
line 81, in Connect
    return Connection(*args, **kwargs)
  File
"/home/pravindr/coding-dojo/py/week4/venv/lib/python2.7/site-packages/MySQLdb/connections.py",
line 206, in __init__
    super(Connection, self).__init__(*args, **kwargs2)
sqlalchemy.exc.OperationalError: (_mysql_exceptions.OperationalError) (2003,
"Can't connect to MySQL server on 'localhost' (111)") (Background on this
error at: http://sqlalche.me/e/e3q8)



ERROR while connecting with user that do not have permission 

Traceback (most recent call last):
  File "server.py", line 8, in <module>
    print mysql.query_db("SELECT * FROM users")
  File
"/home/pravindr/coding-dojo/py/week4/a_mysql_conn_err/mysqlconnection.py",
line 24, in query_db
    result = self.db.session.execute(text(query), data)
  File
"/home/pravindr/coding-dojo/py/week4/venv/lib/python2.7/site-packages/sqlalchemy/orm/scoping.py",
line 153, in do
    return getattr(self.registry(), name)(*args, **kwargs)
  File
"/home/pravindr/coding-dojo/py/week4/venv/lib/python2.7/site-packages/sqlalchemy/orm/session.py",
line 1176, in execute
    bind, close_with_result=True).execute(clause, params or {})
  File
"/home/pravindr/coding-dojo/py/week4/venv/lib/python2.7/site-packages/sqlalchemy/orm/session.py",
line 1040, in _connection_for_bind
    engine, execution_options)
  File
"/home/pravindr/coding-dojo/py/week4/venv/lib/python2.7/site-packages/sqlalchemy/orm/session.py",
line 409, in _connection_for_bind
    conn = bind.contextual_connect()
  File
"/home/pravindr/coding-dojo/py/week4/venv/lib/python2.7/site-packages/sqlalchemy/engine/base.py",
line 2123, in contextual_connect
    self._wrap_pool_connect(self.pool.connect, None),
  File
"/home/pravindr/coding-dojo/py/week4/venv/lib/python2.7/site-packages/sqlalchemy/engine/base.py",
line 2162, in _wrap_pool_connect
    e, dialect, self)
  File
"/home/pravindr/coding-dojo/py/week4/venv/lib/python2.7/site-packages/sqlalchemy/engine/base.py",
line 1476, in _handle_dbapi_exception_noconnection
    exc_info
  File
"/home/pravindr/coding-dojo/py/week4/venv/lib/python2.7/site-packages/sqlalchemy/util/compat.py",
line 203, in raise_from_cause
    reraise(type(exception), exception, tb=exc_tb, cause=cause)
  File
"/home/pravindr/coding-dojo/py/week4/venv/lib/python2.7/site-packages/sqlalchemy/engine/base.py",
line 2158, in _wrap_pool_connect
    return fn()
  File
"/home/pravindr/coding-dojo/py/week4/venv/lib/python2.7/site-packages/sqlalchemy/pool.py",
line 403, in connect
    return _ConnectionFairy._checkout(self)
  File
"/home/pravindr/coding-dojo/py/week4/venv/lib/python2.7/site-packages/sqlalchemy/pool.py",
line 782, in _checkout
    fairy = _ConnectionRecord.checkout(pool)
  File
"/home/pravindr/coding-dojo/py/week4/venv/lib/python2.7/site-packages/sqlalchemy/pool.py",
line 532, in checkout
    rec = pool._do_get()
  File
"/home/pravindr/coding-dojo/py/week4/venv/lib/python2.7/site-packages/sqlalchemy/pool.py",
line 1186, in _do_get
    self._dec_overflow()
  File
"/home/pravindr/coding-dojo/py/week4/venv/lib/python2.7/site-packages/sqlalchemy/util/langhelpers.py",
line 66, in __exit__
    compat.reraise(exc_type, exc_value, exc_tb)
  File
"/home/pravindr/coding-dojo/py/week4/venv/lib/python2.7/site-packages/sqlalchemy/pool.py",
line 1183, in _do_get
    return self._create_connection()
  File
"/home/pravindr/coding-dojo/py/week4/venv/lib/python2.7/site-packages/sqlalchemy/pool.py",
line 350, in _create_connection
    return _ConnectionRecord(self)
  File
"/home/pravindr/coding-dojo/py/week4/venv/lib/python2.7/site-packages/sqlalchemy/pool.py",
line 477, in __init__
    self.__connect(first_connect_check=True)
  File
"/home/pravindr/coding-dojo/py/week4/venv/lib/python2.7/site-packages/sqlalchemy/pool.py",
line 667, in __connect
    connection = pool._invoke_creator(self)
  File
"/home/pravindr/coding-dojo/py/week4/venv/lib/python2.7/site-packages/sqlalchemy/engine/strategies.py",
line 105, in connect
    return dialect.connect(*cargs, **cparams)
  File
"/home/pravindr/coding-dojo/py/week4/venv/lib/python2.7/site-packages/sqlalchemy/engine/default.py",
line 410, in connect
    return self.dbapi.connect(*cargs, **cparams)
  File
"/home/pravindr/coding-dojo/py/week4/venv/lib/python2.7/site-packages/MySQLdb/__init__.py",
line 81, in Connect
    return Connection(*args, **kwargs)
  File
"/home/pravindr/coding-dojo/py/week4/venv/lib/python2.7/site-packages/MySQLdb/connections.py",
line 206, in __init__
    super(Connection, self).__init__(*args, **kwargs2)
sqlalchemy.exc.OperationalError: (_mysql_exceptions.OperationalError) (1045,
"Access denied for user 'pj1'@'localhost' (using password:
YES)") (Background on this error at: http://sqlalche.me/e/e3q8)




